Workbook

Sheet Wykres1

Sheet Stats
A1: NAME | K1: class chosen | L1: =L29 -> 2 | M1: Mixed races? (Yes -1/ No - 0) | P1: skills | Q1: points | R1: reroll | S1: mod | T1: throw
A2: Race | C2: =N4 -> Ork | F2: modificator | H2: to reroll | K2: dmg phs recieved | P2: dodge (ag) | Q2: 0 | R2: =$H$5 -> 9 | T2: =IF(Q2<=19, ROUNDUP(0.5*Q2,0)+R2+S2,R2)+IF(meta!$A$2,1,0) -> 9
A3: lvl | C3: 8 | F3: x | H3: x | K3: dmg mag recieved | M3: MOD | N3: Value | P3: accuracy (ag) | Q3: 0 | R3: =$H$5 -> 9 | T3: =IF(Q3<=19, ROUNDUP(0.5*Q3,0)+R3+S3,R3)+IF(meta!$A$2,1,0) -> 9
A4: strength | C4: 20 | F4: =N5 -> 4 | H4: =ROUNDUP((C4/4)+F4,0) -> 9 | K4: mana spent | M4: Racename | N4: =IF(meta!A1,B28 &"/" & C28,B28) -> Ork | P4: stealth (ag) | Q4: 0 | R4: =$H$5 -> 9 | T4: =IF(Q4<=19, ROUNDUP(0.5*Q4,0)+R4+S4,R4)+IF(meta!$A$2,1,0) -> 9
A5: agilty | C5: 20 | F5: =N6 -> 4 | H5: =ROUNDUP((C5/4)+F5,0) -> 9 | K5: current health | L5: =IF(L$1=1,meta!U44,IF(L$1=2,meta!V44,IF(L$1=3,meta!W44,"Error")))+IF(L7<0,L7,0)+IF(L8<0,(L8),0)+IF(L6<0,L6,0) -> 330 | M5: Mixed str | N5: =IF(meta!A$1,CEILING(AVERAGE(B29,C29),1),B29) -> 4 | P5: lockpick (ag) | Q5: 0 | R5: =$H$5 -> 9 | T5: =IF(Q5<=19, ROUNDUP(0.5*Q5,0)+R5+S5,R5)+IF(meta!$A$2,1,0) -> 9
A6: charisma | C6: 20 | F6: =N7 -> 1 | H6: =ROUNDUP((C6/4)+F6,0) -> 6 | K6: current mana | L6: =IF(L$1=1,meta!U45,IF(L$1=2,meta!V45,IF(L$1=3,meta!W45,"Error")))-L4 -> 210 | M6: Mixed agi | N6: =IF(meta!A$1,CEILING(AVERAGE(B30,C30),1),B30) -> 4 | P6: acrobatics (ag) | Q6: 0 | R6: =$H$5 -> 9 | T6: =IF(Q6<=19, ROUNDUP(0.5*Q6,0)+R6+S6,R6)+IF(meta!$A$2,1,0) -> 9
A7: wisdom | C7: 20 | F7: =N8 -> 0 | H7: =ROUNDUP((C7/4)+F7,0) -> 5 | K7: current shield | L7: =IF(L$1=1,meta!U46,IF(L$1=2,meta!V46,IF(L$1=3,meta!W46,"Error")))-L2+Inventory!E27 -> 110 | M7: Mixed char | N7: =IF(meta!A$1,CEILING(AVERAGE(B31,C31),1),B31) -> 1 | P7: riding (ag) | Q7: 0 | R7: =$H$5 -> 9 | T7: =IF(Q7<=19, ROUNDUP(0.5*Q7,0)+R7+S7,R7)+IF(meta!$A$2,1,0) -> 9
A8: tl -> | C8: =ROUNDUP(((F4+F5+F6+F7)/3),0) -> 3 | F8: points -> | H8: =((C3*2)+4)-SUM(Q2:Q32) -> 20 | K8: current barrier | L8: =IF(L$1=1,meta!U47,IF(L$1=2,meta!V47,IF(L$1=3,meta!W47,"Error")))-L3+Inventory!F27 -> 70 | M8: Mixed wis | N8: =IF(meta!A$1,CEILING(AVERAGE(B32,C32),1),B32) -> 0 | P8: Artistics (ag) | Q8: 0 | R8: =$H$5 -> 9 | T8: =IF(Q8<=19, ROUNDUP(0.5*Q8,0)+R8+S8,R8)+IF(meta!$A$2,1,0) -> 9
A9: death meetings | E9: dice | F9: Abyssal essence only undead | K9: current class | L9: =IF(C$3<20,IF(C$3<8,IF(C$3<4,"Punch",K$29),K$31),K$35) -> veterian | M9: Pc? | P9: pickpocket(ag) | Q9: 0 | R9: =$H$5 -> 9 | T9: =IF(Q9<=19, ROUNDUP(0.5*Q9,0)+R9+S9,R9)+IF(meta!$A$2,1,0) -> 9
K10: current subclass | L10: =IF(C$3<70,IF(C$3<58,IF(C$3<54,IF(C3<50,"brak","punch"),E$29),E$31),E$35) -> brak | M10: Racial alligment | O10: =IF(meta!A1,"none",B34) -> 0 | P10: endurance (str+ag) | Q10: 0 | R10: =H$4+H5 -> 18 | T10: =IF(Q10<=19, ROUNDUP(0.5*Q10,0)+R10+S10,R10)+IF(meta!$A$2,1,0) -> 18
A11: Race alligment | E11: Creature leaning | G11: Matching | K11: <- DESCRIPTION | L11: Armour Class | P11: tackling(str) | Q11: 0 | R11: =H$4 -> 9 | T11: =IF(Q11<=19, ROUNDUP(0.5*Q11,0)+R11+S11,R11)+IF(meta!$A$2,1,0) -> 9
A12: =IF(meta!A1,"none",IF(O10=1,"evil","good")) -> good | E12: =meta!O27 -> none | G12: =IF(A12=E12,"yes","no") -> no | K12: when matching bonus | P12: throw (str) | Q12: 0 | R12: =H$4 -> 9 | T12: =IF(Q12<=19, ROUNDUP(0.5*Q12,0)+R12+S12,R12)+IF(meta!$A$2,1,0) -> 9
A13: PASSIVE PERCEPTION | E13: bonus | G13: total | K13: added to no. of observation success | P13: atletics (str) | Q13: 0 | R13: =H$4 -> 9 | S13: 0 | T13: =IF(Q13<=19, ROUNDUP(0.5*Q13,0)+R13+S13,R13)+IF(meta!$A$2,1,0) -> 9
A14: =FLOOR(meta!L4/4+F7,1) -> 10 | G14: =A14+E14 -> 10 | L14: base | P14: pin(str) | Q14: 0 | R14: =H$4 -> 9 | T14: =IF(Q14<=19, ROUNDUP(0.5*Q14,0)+R14+S14,R14)+IF(meta!$A$2,1,0) -> 9
A15: PASSIVE RESISTANCE | E15: ammount used | G15: left | K15: used while drinking stronger magical effective drinks/ effects | L15: Melee | M15: Ranged | N15: Magical | P15: parry (str) | Q15: 0 | R15: =H$4 -> 9 | S15: 0 | T15: =IF(Q15<=19, ROUNDUP(0.5*Q15,0)+R15+S15,R15)+IF(meta!$A$2,1,0) -> 9
A16: =FLOOR(meta!L6/4+F4,1) -> 14 | G16: =A16-E16 -> 14 | L16: =FLOOR(meta!U54,1) -> 13 | M16: =FLOOR(meta!U54,1) -> 13 | N16: =FLOOR(meta!U54,1) -> 13 | P16: Threathening (str) | Q16: 0 | R16: =H$4 -> 9 | T16: =IF(Q16<=19, ROUNDUP(0.5*Q16,0)+R16+S16,R16)+IF(meta!$A$2,1,0) -> 9
A17: Melee dmg | E17: bonus | G17: total | K17: dmg dealt by bare hands + gauntlets | L17: bonuses | P17: Magical effectiveness (wis) | Q17: 0 | R17: =$H$7 -> 5 | T17: =IF(Q17<=19, ROUNDUP(0.5*Q17,0)+R17+S17,R17)+IF(meta!$A$2,1,0) -> 5
A18: =CEILING(C4/5,1)+1 -> 5 | G18: =A18+E18 & "d6" -> 5d6 | P18: percepction (wis) | Q18: 0 | R18: =$H$7 -> 5 | T18: =IF(Q18<=19, ROUNDUP(0.5*Q18,0)+R18+S18,R18)+IF(meta!$A$2,1,0) -> 5
A19: Movement range | E19: bonus | G19: total | K19: movement in one bonus action of combat | L19: other | P19: intuition (wis) | Q19: 0 | R19: =$H$7 -> 5 | T19: =IF(Q19<=19, ROUNDUP(0.5*Q19,0)+R19+S19,R19)+IF(meta!$A$2,1,0) -> 5
A20: =CEILING(C5/5,1)*1.5 -> 6 | G20: =A20+E20 & "m" -> 6m | P20: willpower (wis) | Q20: 0 | R20: =$H$7 -> 5 | T20: =IF(Q20<=19, ROUNDUP(0.5*Q20,0)+R20+S20,R20)+IF(meta!$A$2,1,0) -> 5
A21: Armour Break | E21: bonus | G21: total Armour Break | K21: <- type -> | L21: | | P21: education (wis) | Q21: 0 | R21: =$H$7 -> 5 | T21: =IF(Q21<=19, ROUNDUP(0.5*Q21,0)+R21+S21,R21)+IF(meta!$A$2,1,0) -> 5
A22: from stats | E22: weapon | F22: other | L22: V sum of armour class | P22: arcane (wis) | Q22: 0 | R22: =$H$7 -> 5 | T22: =IF(Q22<=19, ROUNDUP(0.5*Q22,0)+R22+S22,R22)+IF(meta!$A$2,1,0) -> 5
A23: =C4 -> 20 | G23: =A23+E23+F23 -> 20 | K23: melee | L23: =$L$20+$L$18+$L$16 -> 13 | P23: survival(wis) | Q23: 0 | R23: =$H$7 -> 5 | T23: =IF(Q23<=19, ROUNDUP(0.5*Q23,0)+R23+S23,R23)+IF(meta!$A$2,1,0) -> 5
A24: =C5 -> 20 | G24: =A24+E24+F24 -> 20 | K24: ranged | L24: =$M$20+$M$18+$M$16 -> 13 | P24: medicine (wis) | Q24: 0 | R24: =$H$7 -> 5 | T24: =IF(Q24<=19, ROUNDUP(0.5*Q24,0)+R24+S24,R24)+IF(meta!$A$2,1,0) -> 5
A25: =C7 -> 20 | G25: =A25+E25+F25 -> 20 | K25: magical | L25: =$N$20+$N$18+$N$16 -> 13 | P25: leadership (cha+wis) | Q25: 0 | R25: =H7+H6 -> 11 | S25: 0 | T25: =IF(Q25<=19, ROUNDUP(0.5*Q25,0)+R25+S25,R25)+IF(meta!$A$2,1,0) -> 11
P26: religion (cha+wis) | Q26: 0 | R26: =H7+H6 -> 11 | T26: =IF(Q26<=19, ROUNDUP(0.5*Q26,0)+R26+S26,R26)+IF(meta!$A$2,1,0) -> 11
B27: Etykiety kolumn | E27: SUBCLASS | K27: CLASS | P27: tame (cha) | Q27: 0 | R27: =H$6 -> 6 | T27: =IF(Q27<=19, ROUNDUP(0.5*Q27,0)+R27+S27,R27)+IF(meta!$A$2,1,0) -> 6
A28: Race | B28: Ork | C28: elf | E28: Etykiety wierszy | F28: numer klasy | G28: rank up lvl | K28: Etykiety wierszy | L28: numer klasy | M28: rank up lvl | P28: persuasion(cha) | Q28: 0 | R28: =H$6 -> 6 | T28: =IF(Q28<=19, ROUNDUP(0.5*Q28,0)+R28+S28,R28)+IF(meta!$A$2,1,0) -> 6
A29: str | B29: 4 | C29: 1 | E29: Sword | F29: 2 | G29: 4 | K29: Sword | L29: 2 | M29: 4 | P29: performance(cha) | Q29: 0 | R29: =H$6 -> 6 | T29: =IF(Q29<=19, ROUNDUP(0.5*Q29,0)+R29+S29,R29)+IF(meta!$A$2,1,0) -> 6
A30: agi | B30: 4 | C30: 3 | E30: Etykiety wierszy | F30: numer klasy | G30: rank up lvl | K30: Etykiety wierszy | L30: numer klasy | M30: rank up lvl | P30: deception (cha) | Q30: 0 | R30: =H$6 -> 6 | T30: =IF(Q30<=19, ROUNDUP(0.5*Q30,0)+R30+S30,R30)+IF(meta!$A$2,1,0) -> 6
A31: char | B31: 1 | C31: 2 | E31: ninja | F31: 2 | G31: 8 | K31: veterian | L31: 1 | M31: 8 | P31: intmidation (cha) | Q31: 0 | R31: =H$6 -> 6 | T31: =IF(Q31<=19, ROUNDUP(0.5*Q31,0)+R31+S31,R31)+IF(meta!$A$2,1,0) -> 6
A32: wis | B32: 0 | C32: 3 | E32: 0 | F32: (Wszystko) | K32: poprzednia klasa | L32: veterian | P32: seduction(cha) | Q32: 0 | R32: =H$6 -> 6 | T32: =IF(Q32<=19, ROUNDUP(0.5*Q32,0)+R32+S32,R32)+IF(meta!$A$2,1,0) -> 6
A33: allighment | B33: 0 | C33: 1
E34: Etykiety wierszy | F34: numer klasy | G34: rank up lvl | K34: Etykiety wierszy | L34: numer klasy | M34: rank up lvl
E35: spy | F35: 2 | G35: 20 | K35: zoologist | L35: 1 | M35: 20

Sheet Magic
A1: spellbook | L1: MAGIC TYPE | Q1: Seals
A2: nazwa zaklęcia | B2: School of magic | C2: element alligment | D2: spell type | E2: targetted group (solo/aoe) | F2: range | G2: dmg/heal | H2: effects | I2: casting time | J2: duration | K2: cost | L2: ELEMENTAL MAGIC | Q2: Seal name | S2: Seal type | T2: effect
L3: elemet | M3: lvl | N3: cost multiplier | O3: dmg dice
L4: Fire | M4: 0 | N4: =IF($M4>2,IF($M4>4,IF($M4>6,IF($M4>8,IF($M4>10,IF($M4>12,IF($M4>14,IF($M4>16,IF($M4>18,IF($M4<=20,meta!O$11,meta!O$12),meta!O$10),meta!O$9),meta!O$8),meta!O$7),meta!O$6),meta!O$5),meta!O$4),meta!O$3),meta!O$2) -> d6 | O4: =IF(M4>2,IF(M4>4,IF(M4>6,IF(M4>8,IF(M4>10,IF(M4>12,IF(M4>14,IF(M4>16,IF(M4>18,IF(M4<=20,meta!P$11,meta!P$12),meta!P$10),meta!P$9),meta!P$8),meta!P$7),meta!P$6),meta!P$5),meta!P$4),meta!P$3),meta!P$2) -> 2d6
L5: Earth | M5: 0 | N5: =IF($M5>2,IF($M5>4,IF($M5>6,IF($M5>8,IF($M5>10,IF($M5>12,IF($M5>14,IF($M5>16,IF($M5>18,IF($M5<=20,meta!O$11,meta!O$12),meta!O$10),meta!O$9),meta!O$8),meta!O$7),meta!O$6),meta!O$5),meta!O$4),meta!O$3),meta!O$2) -> d6 | O5: =IF(M5>2,IF(M5>4,IF(M5>6,IF(M5>8,IF(M5>10,IF(M5>12,IF(M5>14,IF(M5>16,IF(M5>18,IF(M5<=20,meta!P$11,meta!P$12),meta!P$10),meta!P$9),meta!P$8),meta!P$7),meta!P$6),meta!P$5),meta!P$4),meta!P$3),meta!P$2) -> 2d6
L6: Air | M6: 0 | N6: =IF($M6>2,IF($M6>4,IF($M6>6,IF($M6>8,IF($M6>10,IF($M6>12,IF($M6>14,IF($M6>16,IF($M6>18,IF($M6<=20,meta!O$11,meta!O$12),meta!O$10),meta!O$9),meta!O$8),meta!O$7),meta!O$6),meta!O$5),meta!O$4),meta!O$3),meta!O$2) -> d6 | O6: =IF(M6>2,IF(M6>4,IF(M6>6,IF(M6>8,IF(M6>10,IF(M6>12,IF(M6>14,IF(M6>16,IF(M6>18,IF(M6<=20,meta!P$11,meta!P$12),meta!P$10),meta!P$9),meta!P$8),meta!P$7),meta!P$6),meta!P$5),meta!P$4),meta!P$3),meta!P$2) -> 2d6
L7: Water | M7: 0 | N7: =IF($M7>2,IF($M7>4,IF($M7>6,IF($M7>8,IF($M7>10,IF($M7>12,IF($M7>14,IF($M7>16,IF($M7>18,IF($M7<=20,meta!O$11,meta!O$12),meta!O$10),meta!O$9),meta!O$8),meta!O$7),meta!O$6),meta!O$5),meta!O$4),meta!O$3),meta!O$2) -> d6 | O7: =IF(M7>2,IF(M7>4,IF(M7>6,IF(M7>8,IF(M7>10,IF(M7>12,IF(M7>14,IF(M7>16,IF(M7>18,IF(M7<=20,meta!P$11,meta!P$12),meta!P$10),meta!P$9),meta!P$8),meta!P$7),meta!P$6),meta!P$5),meta!P$4),meta!P$3),meta!P$2) -> 2d6
L8: Nature | M8: 0 | N8: =IF($M8>2,IF($M8>4,IF($M8>6,IF($M8>8,IF($M8>10,IF($M8>12,IF($M8>14,IF($M8>16,IF($M8>18,IF($M8<=20,meta!O$11,meta!O$12),meta!O$10),meta!O$9),meta!O$8),meta!O$7),meta!O$6),meta!O$5),meta!O$4),meta!O$3),meta!O$2) -> d6 | O8: =IF(M8>2,IF(M8>4,IF(M8>6,IF(M8>8,IF(M8>10,IF(M8>12,IF(M8>14,IF(M8>16,IF(M8>18,IF(M8<=20,meta!P$11,meta!P$12),meta!P$10),meta!P$9),meta!P$8),meta!P$7),meta!P$6),meta!P$5),meta!P$4),meta!P$3),meta!P$2) -> 2d6
L9: Light | M9: 0 | N9: =IF($M9>2,IF($M9>4,IF($M9>6,IF($M9>8,IF($M9>10,IF($M9>12,IF($M9>14,IF($M9>16,IF($M9>18,IF($M9<=20,meta!O$11,meta!O$12),meta!O$10),meta!O$9),meta!O$8),meta!O$7),meta!O$6),meta!O$5),meta!O$4),meta!O$3),meta!O$2) -> d6 | O9: =IF(M9>2,IF(M9>4,IF(M9>6,IF(M9>8,IF(M9>10,IF(M9>12,IF(M9>14,IF(M9>16,IF(M9>18,IF(M9<=20,meta!P$11,meta!P$12),meta!P$10),meta!P$9),meta!P$8),meta!P$7),meta!P$6),meta!P$5),meta!P$4),meta!P$3),meta!P$2) -> 2d6
L10: Darkness | M10: 0 | N10: =IF($M10>2,IF($M10>4,IF($M10>6,IF($M10>8,IF($M10>10,IF($M10>12,IF($M10>14,IF($M10>16,IF($M10>18,IF($M10<=20,meta!O$11,meta!O$12),meta!O$10),meta!O$9),meta!O$8),meta!O$7),meta!O$6),meta!O$5),meta!O$4),meta!O$3),meta!O$2) -> d6 | O10: =IF(M10>2,IF(M10>4,IF(M10>6,IF(M10>8,IF(M10>10,IF(M10>12,IF(M10>14,IF(M10>16,IF(M10>18,IF(M10<=20,meta!P$11,meta!P$12),meta!P$10),meta!P$9),meta!P$8),meta!P$7),meta!P$6),meta!P$5),meta!P$4),meta!P$3),meta!P$2) -> 2d6
L11: Electricity | M11: 0 | N11: =IF($M11>2,IF($M11>4,IF($M11>6,IF($M11>8,IF($M11>10,IF($M11>12,IF($M11>14,IF($M11>16,IF($M11>18,IF($M11<=20,meta!O$11,meta!O$12),meta!O$10),meta!O$9),meta!O$8),meta!O$7),meta!O$6),meta!O$5),meta!O$4),meta!O$3),meta!O$2) -> d6 | O11: =IF(M11>2,IF(M11>4,IF(M11>6,IF(M11>8,IF(M11>10,IF(M11>12,IF(M11>14,IF(M11>16,IF(M11>18,IF(M11<=20,meta!P$11,meta!P$12),meta!P$10),meta!P$9),meta!P$8),meta!P$7),meta!P$6),meta!P$5),meta!P$4),meta!P$3),meta!P$2) -> 2d6
L12: Abyss | M12: 0 | N12: =IF($M12>2,IF($M12>4,IF($M12>6,IF($M12>8,IF($M12>10,IF($M12>12,IF($M12>14,IF($M12>16,IF($M12>18,IF($M12<=20,meta!O$11,meta!O$12),meta!O$10),meta!O$9),meta!O$8),meta!O$7),meta!O$6),meta!O$5),meta!O$4),meta!O$3),meta!O$2) -> d6 | O12: =IF(M12>2,IF(M12>4,IF(M12>6,IF(M12>8,IF(M12>10,IF(M12>12,IF(M12>14,IF(M12>16,IF(M12>18,IF(M12<=20,meta!P$11,meta!P$12),meta!P$10),meta!P$9),meta!P$8),meta!P$7),meta!P$6),meta!P$5),meta!P$4),meta!P$3),meta!P$2) -> 2d6
L13: Time | M13: 0 | N13: =IF($M13>1,IF($M13>2,IF($M13>3,IF($M13>4,IF($M13>5,IF($M13>6,IF($M13>7,IF($M13>8,IF($M13>9,IF($M13<=10,meta!O$11,meta!O$12),meta!O$10),meta!O$9),meta!O$8),meta!O$7),meta!O$6),meta!O$5),meta!O$4),meta!O$3),meta!O$2) -> d6 | O13: =IF(M13>1,IF(M13>2,IF(M13>3,IF(M13>4,IF(M13>5,IF(M13>6,IF(M13>7,IF(M13>8,IF(M13>9,IF(M13<=10,meta!P$11,meta!P$12),meta!P$10),meta!P$9),meta!P$8),meta!P$7),meta!P$6),meta!P$5),meta!P$4),meta!P$3),meta!P$2) -> 2d6
L14: Fate | M14: 0 | N14: =IF($M14>1,IF($M14>2,IF($M14>3,IF($M14>4,IF($M14>5,IF($M14>6,IF($M14>7,IF($M14>8,IF($M14>9,IF($M14<=10,meta!O$11,meta!O$12),meta!O$10),meta!O$9),meta!O$8),meta!O$7),meta!O$6),meta!O$5),meta!O$4),meta!O$3),meta!O$2) -> d6 | O14: =IF(M14>1,IF(M14>2,IF(M14>3,IF(M14>4,IF(M14>5,IF(M14>6,IF(M14>7,IF(M14>8,IF(M14>9,IF(M14<=10,meta!P$11,meta!P$12),meta!P$10),meta!P$9),meta!P$8),meta!P$7),meta!P$6),meta!P$5),meta!P$4),meta!P$3),meta!P$2) -> 2d6
L15: Duplication | M15: 0 | N15: =IF($M15>1,IF($M15>2,IF($M15>3,IF($M15>4,IF($M15>5,IF($M15>6,IF($M15>7,IF($M15>8,IF($M15>9,IF($M15<=10,meta!O$11,meta!O$12),meta!O$10),meta!O$9),meta!O$8),meta!O$7),meta!O$6),meta!O$5),meta!O$4),meta!O$3),meta!O$2) -> d6 | O15: =IF(M15>1,IF(M15>2,IF(M15>3,IF(M15>4,IF(M15>5,IF(M15>6,IF(M15>7,IF(M15>8,IF(M15>9,IF(M15<=10,meta!P$11,meta!P$12),meta!P$10),meta!P$9),meta!P$8),meta!P$7),meta!P$6),meta!P$5),meta!P$4),meta!P$3),meta!P$2) -> 2d6
L16: Chaos | M16: 0 | N16: =IF($M16>1,IF($M16>2,IF($M16>3,IF($M16>4,IF($M16>5,IF($M16>6,IF($M16>7,IF($M16>8,IF($M16>9,IF($M16<=10,meta!O$11,meta!O$12),meta!O$10),meta!O$9),meta!O$8),meta!O$7),meta!O$6),meta!O$5),meta!O$4),meta!O$3),meta!O$2) -> d6 | O16: =IF(M16>1,IF(M16>2,IF(M16>3,IF(M16>4,IF(M16>5,IF(M16>6,IF(M16>7,IF(M16>8,IF(M16>9,IF(M16<=10,meta!P$11,meta!P$12),meta!P$10),meta!P$9),meta!P$8),meta!P$7),meta!P$6),meta!P$5),meta!P$4),meta!P$3),meta!P$2) -> 2d6
L17: Creation | M17: 0 | N17: =IF($M17>2,IF($M17>4,IF($M17>6,IF($M17>8,IF($M17>10,IF($M17>12,IF($M17>14,IF($M17>16,IF($M17>18,IF($M17<=20,meta!O$11,meta!O$12),meta!O$10),meta!O$9),meta!O$8),meta!O$7),meta!O$6),meta!O$5),meta!O$4),meta!O$3),meta!O$2) -> d6 | O17: =IF(M17>2,IF(M17>4,IF(M17>6,IF(M17>8,IF(M17>10,IF(M17>12,IF(M17>14,IF(M17>16,IF(M17>18,IF(M17<=20,meta!P$11,meta!P$12),meta!P$10),meta!P$9),meta!P$8),meta!P$7),meta!P$6),meta!P$5),meta!P$4),meta!P$3),meta!P$2) -> 2d6
L18: Symbol Magic | M18: LVL | N18: quick use cost | P18: des | R18: elemental | S18: symbol
L19: Runes | M19: 0 | N19: =IF($M19>1,IF($M19>2,IF($M19>3,IF($M19>4,IF($M19>5,IF($M19>6,IF($M19>7,IF($M19>8,IF($M19>9,IF($M19<=10,meta!O$49,meta!O$12),meta!O$48),meta!O$47),meta!O$46),meta!O$45),meta!O$44),meta!O$43),meta!O$42),meta!O$41),meta!O$40) -> d6 | O19: =IF($M19>1,IF($M19>2,IF($M19>3,IF($M19>4,IF($M19>5,IF($M19>6,IF($M19>7,IF($M19>8,IF($M19>9,IF($M19<=10,meta!P$49,"błąd"),meta!P$48),meta!P$47),meta!P46),meta!P$45),meta!P44),meta!P$43),meta!P42),meta!P$41),meta!P$40) -> 1 | P19: ammount of symboles | Q19: current | R19: =SUM(M4:M17) -> 0 | S19: =SUM(M19:M22) -> 0
L20: Glyphs | M20: 0 | N20: =IF(M20<>1,IF(M20<>2,IF(M20<>3,IF(M20<>4,IF(M20=5,meta!O36),meta!O35),meta!O34),meta!O33),meta!O32) -> FALSE | O20: =IF(M20<>1,IF(M20<>2,IF(M20<>3,IF(M20<>4,IF(M20=5,meta!P36),meta!P35),meta!P34),meta!P33),meta!P32) -> FALSE | P20: ammount of parts | Q20: max | R20: 240 | S20: 24
L21: Commands | M21: 0 | N21: =IF(M21<>1,IF(M21<>2,IF(M21<>3,IF(M21<>4,IF(M21=5,meta!O36),meta!O35),meta!O34),meta!O33),meta!O32) -> FALSE | O21: =IF(M21<>1,IF(M21<>2,IF(M21<>3,IF(M21<>4,IF(M21=5,"5d10","error"),"4d10"),"3d10"),"2d10"),"1d10") -> error | P21: basic strength | R21: =R19/R20 -> 0 | S21: =S19/S20 -> 0
L22: Seals | M22: 0 | N22: =IF(M22<>1,IF(M22<>2,IF(M22<>3,IF(M22=4,"d12*d6","error"),"d10*d6"),"d12*d4"),"d10*d4") -> error | O22: =IF(M22<>1,IF(M22<>2,IF(M22<>3,IF(M22=4,"master","error"),"expert"),"advanced"),"basic") -> error | P22: advancement lvl
L24: magic multiplayer
P25: 0 | Q25: 0
L26: element | M26: staff/wand mult | N26: scepter | O26: cape mult | P26: lvl of mastery ^ for> | Q26: catalyst 1 | R26: catalyst 2 | S26: catalyst 3 | T26: catalyst 4 | U26: rest | V26: total
L27: Fire | M27: 0.5 | P27: =$P$25 -> 0 | Q27: =P27*Q$25 -> 0 | R27: =$P$25*R25 -> 0 | S27: =$P$25*S25 -> 0 | T27: =$P$25*T25 -> 0 | U27: 0 | V27: =SUM(M27:O27,Q27:U27)+1 -> 1.5
L28: Earth | M28: 0.5 | P28: =$P$25 -> 0 | U28: 0 | V28: =SUM(M28:O28,Q28:U28)+1 -> 1.5
L29: Air | M29: 0.5 | P29: =$P$25 -> 0 | U29: 0 | V29: =SUM(M29:O29,Q29:U29)+1 -> 1.5
L30: Water | M30: 0.5 | P30: =$P$25 -> 0 | U30: 0 | V30: =SUM(M30:O30,Q30:U30)+1 -> 1.5
L31: Nature | M31: 0.5 | P31: =$P$25 -> 0 | U31: 0 | V31: =SUM(M31:O31,Q31:U31)+1 -> 1.5
L32: Light | M32: 0.5 | P32: =$P$25 -> 0 | U32: 0 | V32: =SUM(M32:O32,Q32:U32)+1 -> 1.5
L33: Darkness | M33: 0.5 | P33: =$P$25 -> 0 | U33: 0 | V33: =SUM(M33:O33,Q33:U33)+1 -> 1.5
L34: Electricity | M34: 0.5 | P34: =$P$25 -> 0 | U34: 0 | V34: =SUM(M34:O34,Q34:U34)+1 -> 1.5
L35: Abyss | M35: 0.5 | P35: =$P$25 -> 0 | U35: 0 | V35: =SUM(M35:O35,Q35:U35)+1 -> 1.5
L36: Time | M36: 0.5 | P36: =$P$25 -> 0 | U36: 0 | V36: =SUM(M36:O36,Q36:U36)+1 -> 1.5
L37: Fate | M37: 0.5 | P37: =$P$25 -> 0 | U37: 0 | V37: =SUM(M37:O37,Q37:U37)+1 -> 1.5
L38: Duplication | M38: 0.5 | P38: =$P$25 -> 0 | U38: 0 | V38: =SUM(M38:O38,Q38:U38)+1 -> 1.5
L39: Chaos | M39: 0.5 | P39: =$P$25 -> 0 | U39: 0 | V39: =SUM(M39:O39,Q39:U39)+1 -> 1.5
L40: Creation | M40: 0.5 | P40: =$P$25 -> 0 | U40: 0 | V40: =SUM(M40:O40,Q40:U40)+1 -> 1.5

Sheet Inventory
A1: Skills | D1: money | E1: input | F1: output | G1: inventory | K1: max capacity
A2: Hero of Great cause | D2: copper | F2: =E2+F3*100 -> 0 | G2: ilość | H2: item name | I2: slot | J2: des | K2: =CEILING(Stats!C4/5,1)*10 -> 40
D3: silver | F3: =E3+F4*100 -> 0 | K3: current capacity used
D4: gold | F4: =E4+F5*100 -> 0 | K4: =SUM(I3:I6000)-SUM(F31:F40) -> 0
D5: diamond | F5: =E5+F6*100 -> 0
D6: emeralnd | F6: =E6+F7*100 -> 0
D7: ruby | F7: =E7+F8*100 -> 0
D8: saphire | F8: =E8+F9*100 -> 0
D9: platinum | F9: =E9+F10*100 -> 0
D11: elements | E11: input
D12: red | F12: from animals
D13: green | F13: from plant based
D14: yellow | F14: from minerals/metals/bones
D15: blue | F15: from liquids
D16: white | F16: from sacntus
D17: black | F17: from profanities
D19: Armour | E19: shield bonus | F19: barrier bonus
D20: helmet | E20: 0
D21: Chestplate
D22: Gauntlets
D23: Leggins
D24: Boots
D25: Cape
D26: Other
D27: sum | E27: =SUM(E20:E26) -> 0 | F27: =SUM(F20:F26) -> 0
D29: Equipable weaponry
D30: place | E30: name | F30: slots
D31: left hand
D32: right hand
D33: back 1
D34: back 2
D35: back 3
D36: belt 1
D37: belt 2
D38: belt 3
D39: belt 4
D40: necklace
D41: bracelet 1
D42: bracelet 2

Sheet meta
A1: FALSE | C1: modyfikator -> | D1: allighment | E1: strength | F1: agility | G1: charisma | H1: wisdom | I1: Spec ability | J1: tl | O1: kostki do kosztu | P1: kostki do algorytmu | Q1: max dmg | R1: max koszt | S1: dmg/koszt ratio | U1: lvl req | V1: klasa | W1: typ klasy | Y1: lvl req | Z1: klasa | AA1: typ klasy | AB1: indeks klasy | AM1: s
A2: FALSE | C2: Rasa VVV | E2: x | F2: x | G2: x | H2: x | N2: 1.2 | O2: d6 | P2: 2d6 | Q2: 12 | R2: 6 | S2: =Q2/R2 -> 2 | U2: 4 | V2: Adept | W2: 1 | Y2: 8 | Z2: sage | AA2: 1 | AB2: s
A3: Shallow | B3: =B2+1 -> 1 | C3: human | D3: 1 | E3: 2 | F3: 2 | G3: 0 | H3: 1 | J3: =ROUNDUP(SUM(E3:H3)/3,0) -> 2 | N3: 3.4 | O3: d8 | P3: 3d6 | Q3: 18 | R3: 8 | S3: =Q3/R3 -> 2.25 | U3: 4 | V3: Sword | W3: 2 | Y3: 8 | Z3: veterian | AA3: 1 | AB3: v
A4: uderya | B4: =B3+1 -> 2 | C4: elf | D4: 1 | E4: 1 | F4: 3 | G4: 2 | H4: 3 | J4: =ROUNDUP(SUM(E4:H4)/3,0) -> 3 | L4: =Stats!C5+Stats!C7 -> 40 | N4: 5.6 | O4: d10 | P4: 3d8 | Q4: 24 | R4: 10 | S4: =Q4/R4 -> 2.4 | U4: 4 | V4: Ranger | W4: 3 | Y4: 8 | Z4: mage | AA4: 1 | AB4: m
A5: paltonia | B5: =B4+1 -> 3 | C5: dwarf | D5: 1 | E5: 4 | F5: 0 | G5: 1 | H5: 2 | J5: =ROUNDUP(SUM(E5:H5)/3,0) -> 3 | N5: 7.8 | O5: d12 | P5: 3d10 | Q5: 30 | R5: 12 | S5: =Q5/R5 -> 2.5 | Y5: 8 | Z5: barbarian | AA5: 2 | AB5: b
A6: Casede | B6: =B5+1 -> 4 | C6: halfling | D6: 1 | E6: 1 | F6: 1 | G6: 1 | H6: 1 | J6: =ROUNDUP(SUM(E6:H6)/3,0) -> 2 | L6: =Stats!C4+Stats!C5 -> 40 | N6: 9,10. | O6: d20 | P6: 3d20 | Q6: 60 | R6: 20 | S6: =Q6/R6 -> 3 | Y6: 8 | Z6: ninja | AA6: 2 | AB6: n
B7: =B6+1 -> 5 | C7: undead skeleton | D7: 0 | E7: 1 | F7: 2 | G7: 0 | H7: 0 | I7: reconstruction - doesn't lose abysal energy for returning | J7: =ROUNDUP(SUM(E7:H7)/3,0) -> 1 | N7: 11.12 | O7: (d20+d10) | P7: 4d20 | Q7: 80 | R7: 30 | S7: =Q7/R7 -> 2.6666667 | Y7: 8 | Z7: knight | AA7: 2 | AB7: k
B8: =B7+1 -> 6 | C8: undead vampire | D8: 0 | E8: 1 | F8: 1 | G8: 3 | H8: 2 | J8: =ROUNDUP(SUM(E8:H8)/3,0) -> 3 | N8: 13.14 | O8: 2d20 | P8: d100 | Q8: 100 | R8: 40 | S8: =Q8/R8 -> 2.5 | Y8: 8 | Z8: archer | AA8: 3 | AB8: a
B9: =B8+1 -> 7 | C9: undead banshee | D9: 0 | E9: 0 | F9: 2 | G9: 0 | H9: 2 | J9: =ROUNDUP(SUM(E9:H9)/3,0) -> 2 | N9: 15.16 | O9: 4d20 | P9: 2d100 | Q9: 200 | R9: 80 | S9: =Q9/R9 -> 2.5 | Y9: 8 | Z9: hunter | AA9: 3 | AB9: h
B10: =B9+1 -> 8 | C10: undead wraith | D10: 0 | E10: 2 | F10: 2 | G10: -1 | H10: 2 | J10: =ROUNDUP(SUM(E10:H10)/3,0) -> 2 | N10: 17.18 | O10: d100+2d12 | P10: 3d100 | Q10: 300 | R10: 124 | S10: =Q10/R10 -> 2.4193548 | Y10: 8 | Z10: gunslinger | AA10: 3 | AB10: g
B11: =B10+1 -> 9 | C11: undead zombie | D11: 0 | E11: 3 | F11: 2 | G11: -1 | H11: 0 | J11: =ROUNDUP(SUM(E11:H11)/3,0) -> 2 | N11: 19,20. | O11: 2d100 | P11: 4d100 | Q11: 400 | R11: 200 | S11: =Q11/R11 -> 2
B12: =B11+1 -> 10 | C12: undead werewolf | D12: 0 | E12: 4 | F12: 2 | G12: -1 | H12: 0 | J12: =ROUNDUP(SUM(E12:H12)/3,0) -> 2 | O12: error | P12: error
B13: =B12+1 -> 11 | C13: undead ghost | D13: 0 | E13: -2 | F13: 4 | G13: 0 | H13: 3 | J13: =ROUNDUP(SUM(E13:H13)/3,0) -> 2 | U13: lvl req | V13: klasa | W13: typ klasy | X13: poprzednia klasa
B14: =B13+1 -> 12 | C14: undead mummy | D14: 0 | E14: 4 | F14: 0 | G14: 0 | H14: 2 | J14: =ROUNDUP(SUM(E14:H14)/3,0) -> 2 | U14: 20 | V14: chemist | W14: 1 | X14: sage
B15: =B14+1 -> 13 | C15: undead lich | D15: 0 | E15: 0 | F15: 0 | G15: 0 | H15: 1 | I15: death affinity (bonus to resurection spells/magic) | J15: =ROUNDUP(SUM(E15:H15)/3,0) -> 1 | U15: 20 | V15: artificer | W15: 1 | X15: sage
B16: =B15+1 -> 14 | C16: ents oak | D16: 1 | E16: 3 | F16: 2 | G16: 2 | H16: 2 | J16: =ROUNDUP(SUM(E16:H16)/3,0) -> 3 | U16: 20 | V16: scientist | W16: 1 | X16: sage
B17: =B16+1 -> 15 | C17: ents baobab | D17: 1 | E17: 5 | F17: -1 | G17: 1 | H17: 4 | J17: =ROUNDUP(SUM(E17:H17)/3,0) -> 3 | O17: standard health | P17: =ROUNDUP((Stats!C4*Stats!C5*Stats!C8)/20,0) -> 60 | U17: 20 | V17: zoologist | W17: 1 | X17: veterian
B18: =B17+1 -> 16 | C18: ents spruce | D18: 1 | E18: 2 | F18: 1 | G18: 3 | H18: 3 | J18: =ROUNDUP(SUM(E18:H18)/3,0) -> 3 | O18: standard mana | P18: =ROUNDUP(Stats!C6*Stats!C7*Stats!C8/20,0) -> 60 | U18: 20 | V18: druid | W18: 1 | X18: veterian
B19: =B18+1 -> 17 | C19: entc willow | D19: 1 | E19: 0 | F19: 5 | G19: 2 | H19: 2 | J19: =ROUNDUP(SUM(E19:H19)/3,0) -> 3 | O19: lvl po 4 - ilość | P19: =IF(ROUNDUP(Stats!C3-4,0)<0,0,ROUNDUP(Stats!C3-4,0)) -> 4 | U19: 20 | V19: shaman | W19: 1 | X19: veterian
B20: =B19+1 -> 18 | C20: ent cherry | D20: 1 | E20: 1 | F20: 0 | G20: 7 | H20: 1 | J20: =ROUNDUP(SUM(E20:H20)/3,0) -> 3 | O20: lvl 4 hp | P20: =ROUNDUP($P$17*2.5,0) -> 150 | Q20: =ROUNDUP($P$17*2.5,0) -> 150 | R20: =ROUNDUP($P$17*2.5,0) -> 150 | U20: 20 | V20: warlock | W20: 1 | X20: mage
B21: =B20+1 -> 19 | C21: ent birch | D21: 1 | E21: 2 | F21: 2 | G21: 3 | H21: -4 | I21: Quick recovery (passive healing of hp) | J21: =ROUNDUP(SUM(E21:H21)/3,0) -> 1 | O21: lvl po 4 hp | P21: =ROUNDUP($P$17*$P$19*0.25,0) -> 60 | Q21: =ROUNDUP($P$17*$P$19*0.75,0) -> 180 | R21: =ROUNDUP($P$17*$P$19*0.5,0) -> 120 | U21: 20 | V21: wizard | W21: 1 | X21: mage
B22: =B21+1 -> 20 | C22: ent pine | D22: 1 | E22: 6 | F22: 0 | G22: 0 | H22: 3 | J22: =ROUNDUP(SUM(E22:H22)/3,0) -> 3 | O22: lvl 4 mana | P22: =ROUNDUP($P$18*2.5,0) -> 150 | Q22: =ROUNDUP($P$18*2.5,0) -> 150 | R22: =ROUNDUP($P$18*2.5,0) -> 150 | U22: 20 | V22: sorcerer | W22: 1 | X22: mage
B23: =B22+1 -> 21 | C23: ent maple | D23: 1 | E23: 2 | F23: -1 | G23: 5 | H23: 2 | J23: =ROUNDUP(SUM(E23:H23)/3,0) -> 3 | O23: lvl po 4 mana | P23: =ROUNDUP($P$18*$P$19*0.75,0) -> 180 | Q23: =ROUNDUP($P$18*$P$19*0.25,0) -> 60 | R23: =ROUNDUP($P$18*$P$19*0.5,0) -> 120 | U23: 20 | V23: berserker | W23: 2 | X23: barbarian
B24: =B23+1 -> 22 | C24: ent cypress | D24: 1 | E24: 3 | F24: 0 | G24: 0 | H24: 4 | J24: =ROUNDUP(SUM(E24:H24)/3,0) -> 3 | U24: 20 | V24: bard | W24: 2 | X24: barbarian
B25: =B24+1 -> 23 | C25: ent chestnut | D25: 1 | E25: 4 | F25: 2 | G25: 4 | H25: -1 | J25: =ROUNDUP(SUM(E25:H25)/3,0) -> 3 | U25: 20 | V25: commander | W25: 2 | X25: barbarian
B26: =B25+1 -> 24 | C26: ent Yew | D26: 1 | E26: 3 | F26: -6 | G26: 3 | H26: 3 | I26: Deathless (considered undead ent, immune to death spells/ poisons/ acids) | J26: =ROUNDUP(SUM(E26:H26)/3,0) -> 1 | O26: Aura czystości | P26: =Inventory!E16-Inventory!E17 -> 0 | U26: 20 | V26: spy | W26: 2 | X26: ninja
B27: =B26+1 -> 25 | C27: ent sequoia | D27: 1 | E27: 5 | F27: -4 | G27: 7 | H27: 7 | I27: Monument (every action must be preceded by willpower test) | J27: =ROUNDUP(SUM(E27:H27)/3,0) -> 5 | O27: =IF(meta!P26<>0,IF(meta!P26>50,"good",IF(meta!P26<-50,"evil","none")),"none") -> none | P27: =IF(meta!P26<>0,IF(meta!P26>50,1,IF(meta!P26<-50,-1,0)),0) -> 0 | U27: 20 | V27: shadow | W27: 2 | X27: ninja
B28: =B27+1 -> 26 | C28: fairy | D28: 1 | E28: -2 | F28: 3 | G28: 1 | H28: 1 | I28: Small - +1 sukces do wszytkiego z ag | J28: =ROUNDUP(SUM(E28:H28)/3,0) -> 1 | U28: 20 | V28: rouge | W28: 2 | X28: ninja
B29: =B28+1 -> 27 | C29: Thiefling | D29: 0 | E29: 2 | F29: 1 | G29: 4 | H29: 2 | J29: =ROUNDUP(SUM(E29:H29)/3,0) -> 3 | U29: 20 | V29: paladin | W29: 2 | X29: knight
B30: =B29+1 -> 28 | C30: Dracon | D30: 1 | E30: 4 | F30: 2 | G30: 2 | H30: 3 | J30: =ROUNDUP(SUM(E30:H30)/3,0) -> 4 | N30: glyphs table | U30: 20 | V30: Guardian | W30: 2 | X30: knight
B31: =B30+1 -> 29 | C31: Goblin | D31: 0 | E31: 1 | F31: 3 | G31: 1 | H31: 1 | J31: =ROUNDUP(SUM(E31:H31)/3,0) -> 2 | N31: lvl | O31: cost | P31: ammount of elements | U31: 20 | V31: samurai | W31: 2 | X31: knight
B32: =B31+1 -> 30 | C32: Ork | D32: 0 | E32: 4 | F32: 4 | G32: 1 | H32: 0 | J32: =ROUNDUP(SUM(E32:H32)/3,0) -> 3 | N32: 1 | O32: d12 *3 | P32: 3 | U32: 20 | V32: longbow | W32: 3 | X32: archer
B33: =B32+1 -> 31 | C33: Gnoll | D33: 0 | E33: 3 | F33: 4 | G33: -2 | H33: -1 | J33: =ROUNDUP(SUM(E33:H33)/3,0) -> 2 | N33: 2 | O33: d12 *4 | P33: 5 | U33: 20 | V33: magical archer | W33: 3 | X33: archer
B34: =B33+1 -> 32 | C34: Tabaxi | D34: 1 | E34: -1 | F34: 5 | G34: 2 | H34: 0 | J34: =ROUNDUP(SUM(E34:H34)/3,0) -> 2 | N34: 3 | O34: d20 *3 | P34: 7 | U34: 20 | V34: crossbow | W34: 3 | X34: archer
B35: =B34+1 -> 33 | C35: Waterling | D35: 1 | E35: 1 | F35: 2 | G35: 1 | H35: 1 | J35: =ROUNDUP(SUM(E35:H35)/3,0) -> 2 | N35: 4 | O35: d20*4 | P35: 9 | U35: 20 | V35: trapper | W35: 3 | X35: hunter
B36: =B35+1 -> 34 | C36: construct Golem | D36: 1 | E36: 4 | F36: 4 | G36: 0 | H36: 3 | I36: malfunction (electric, water, earth magic - stuns) | J36: =ROUNDUP(SUM(E36:H36)/3,0) -> 4 | N36: 5 | O36: d20*6 | P36: 10 | U36: 20 | V36: tube shooter | W36: 3 | X36: hunter
B37: =B36+1 -> 35 | C37: construct Gargoyle | D37: 1 | E37: 3 | F37: 3 | G37: 3 | H37: 3 | I37: weak legs (must use fly/wings to move can't fly non stop) | J37: =ROUNDUP(SUM(E37:H37)/3,0) -> 4 | U37: 20 | V37: pirate | W37: 3 | X37: hunter
B38: =B37+1 -> 36 | C38: construct mimic | D38: 0 | E38: 1 | F38: 4 | G38: 2 | H38: 1 | J38: =ROUNDUP(SUM(E38:H38)/3,0) -> 3 | N38: rune table | U38: 20 | V38: marksman | W38: 3 | X38: gunslinger
B39: =B38+1 -> 37 | C39: construct Doll/toys | D39: 1 | E39: -2 | F39: -2 | G39: 5 | H39: 1 | I39: variable (depending on a toy type can do various things | J39: =ROUNDUP(SUM(E39:H39)/3,0) -> 1 | N39: lvl | O39: cost | P39: rune elements | U39: 20 | V39: engineer | W39: 3 | X39: gunslinger
B40: =B39+1 -> 38 | C40: Half-elf | D40: 1 | E40: 1 | F40: 2 | G40: 1 | H40: 2 | J40: =ROUNDUP(SUM(E40:H40)/3,0) -> 2 | N40: 1 | O40: d6 | P40: 1 | U40: 20 | V40: bounty hunter | W40: 3 | X40: gunslinger
...
